Workbook

Sheet OVERVIEW
A1: VNRacing — Item & Car Master
A2: Nakama item_catalog · UE DataTable sync reference · GDD v2 | Sheet v3
A4: Sheet | B4: Purpose | C4: Est. Rows | D4: Key FK
A5: ITEM_MASTER | B5: All Items Collections | C5: ~170 | D5: — | H5: SCHEMA GIẢI THÍCH (Tham khảo mối quan hệ)
A6: CAR_REGISTRY | B6: 15 cars × city × archetype | C6: ~3 | D6: —
A7: ITEM_VISUAL | B7: ccv items gắn với car_id FK | C7: ~150 | D7: car_id → CAR_REGISTRY
A8: ITEM_PERF | B8: ccp items generic (no car_id) | C8: ~1 | D8: ---
A9: LOOT_TABLE | B9: Loot box drop pools + weight | C9: --- | D9: ---
A10: CHANGELOG | B10: Record Changes | C10: — | D10: —
A11: CITY_LOOT_POOL | B11: 5-city loot pool (filter city_id) | C11: ~170 | D11: item_catalog_id → CATALOG_MASTER
A13: QUY TRÌNH UPDATE VÀ THÊM MỚI
A14: 1. Update Item mới trong bảng Master Item, Update tất cả các trường
A15: 2. Copy Item ID và Paste vào bảng Item Visual hay Item Performance tương ứng
A16: 3. Điền thông tin còn lại trong các bảng Item Visual hay Item Performance
A17: 4. UPDATE CÁC THAY ĐỔI VÀO CHANGELOG
A18: QUY TRÌNH XÓA
A19: 1. Chuyển trạng thái Item thành Decaprated.
A20: 2. KHÔNG ĐƯỢC PHÉP XÓA ITEM ĐÃ THÊM
A21: 3. UPDATE CÁC THAY ĐỔI VÀO CHANGELOG
A22: ITEM ID STRUCTURE
A23: {category}_{subcategory}_{descriptor}_{nn}
A24: Segment | B24: Vai trò | C24: Format | D24: Ví dụ
A25: category | B25: Loại item (prefix) | C25: 2–4 ký tự thường | D25: ccv / ccp / cur / loot
A26: subcategory | B26: Subtype trong category | C26: lowercase snake_case | D26: part / mat / bundle_cash
A27: descriptor | B27: Tên / biến thể cụ thể của item | C27: lowercase snake_case | D27: fb / rb / wheel / body
A28: nn | B28: Running index (zero-padded) | C28: ≥ 4 chữ số | 0001→9999→00001 | D28: 0001 / 0002 / … / 00001
A30: Ví dụ đặt tên:
A31: ccv_part_fb_01
A32: └─ ccv | B32: category | C32: Car Customize Visual
A33: └─ part | B33: subcategory | C33: Visual Parts
A34: └─ fb | B34: descriptor | C34: Tên item cụ thể
A35: └─ 01 | B35: nn | C35: Running index #1
A37: Quy tắc bắt buộc
A38: Regex | B38: ^[a-z][a-z0-9_]{2,63}$ | Max 64 ký tự | Chỉ chữ thường + số + dấu _
A39: Immutable | B39: catalog_id KHÔNG được đổi tên sau khi release → chỉ DEPRECATE, ghi CHANGELOG
A40: No reuse | B40: ID đã deprecated → không tái sử dụng, tạo ID mới với index tiếp theo

Sheet CITY_LIST
A1: VNRacing — City List (City List dự kiến)
A2: 5 thành phố theo thứ tự unlock · CR range tham chiếu từ Vehicle Stat System v2.1
A3: unlock_order | B3: city_id | C3: city_name_VN | D3: city_name_EN | E3: CR_min | F3: CR_max | G3: notes
A4: 1 | B4: DN | C4: Đà Nẵng | D4: Da Nang | E4: 0 | F4: 6 | G4: Thành phố mở đầu · Starter car unlock · CR 0–6
A5: 2 | B5: HU | C5: Huế | D5: Hue Ancient Capital | E5: 4 | F5: 9 | G5: CR 4–9 · Beach circuit · Mid-early progression
A6: 3 | B6: NT | C6: Nha Trang | D6: Nha Trang | E6: 7 | F6: 12 | G6: CR 7–12 · Coastal highway · Mid game
A7: 4 | B7: HCM | C7: Hồ Chí Minh | D7: Ho Chi Minh | E7: 10 | F7: 15 | G7: CR 10–15 · Urban circuit · Late game
A8: 5 | B8: PQ | C8: Phú Quốc | D8: Phu Quoc | E8: 13 | F8: 18 | G8: CR 13–18 · Island endgame · Max progression
A10: CR Range tham chiếu: Early game CR 0–6 · Mid game CR 6–12 · Late game CR 12–18
A12: PHASE REFERENCE
A13: Phase | B13: Cities | C13: CR Range | D13: WinRate Target | E13: Difficulty
A14: Early | B14: DN → HU | C14: CR 0–6 | D14: 0.55–0.70 | E14: Easy — player wins often
A15: Mid | B15: NT → HCM | C15: CR 6–12 | D15: 0.45–0.60 | E15: Balanced — skill gap widens
A16: Late | B16: HCM → PQ | C16: CR 12–18 | D16: 0.35–0.50 | E16: Hard — upgrade pressure max

Sheet ITEM_MASTER
A1: item_id | B1: category | C1: subcategory | D1: display_name_EN | E1: display_name_VN | F1: on_use_effect | G1: rarity | H1: status | I1: unlock_source | J1: file_path | K1: icon_path | L1: shop_exclusive | M1: reward_eligibles | N1: notes
A2: SoT cho item definition · Hướng B: sheet con chỉ lưu trường đặc thù, display_name kéo về bằng VLOOKUP · catalog_id immutable sau release
A3: ── Car Customize Visual (ccv) ──
A4: ccv_part_fb_0001 | B4: ccv | C4: part | D4: Front Bumper Basic | E4: Cản Trước Tiêu Chuẩn | G4: Common | H4: unreleased | I4: Car Defaults | J4: /Content/Vehicles/Lux_A/Mesh/FrontBumper/SM_LuxA_FrontBumper_Basic.uasset | K4: path_i | L4: FALSE | M4: TRUE
A5: ccv_part_rb_0001 | B5: ccv | C5: part | D5: Rear Bumper Basic | E5: Cản Sau Tiêu Chuẩn | G5: Common | H5: unreleased | I5: Car Defaults | J5: /Content/Vehicles/Lux_A/Mesh/RearBumper/SM_LuxA_RearBumper_Basic.uasset | L5: FALSE | M5: TRUE
A6: ccv_part_sp_0001 | B6: ccv | C6: part | D6: Spoiler Basic | E6: Cánh Gió Tiêu Chuẩn | G6: Common | H6: unreleased | I6: Car Defaults | J6: /Content/Vehicles/Lux_A/Mesh/Spoiler/SM_LuxA_Spoiler_Basic.uasset | L6: FALSE | M6: TRUE
A7: ccv_part_ro_0001 | B7: ccv | C7: part | D7: Roof Panel Basic | E7: Nóc Xe Tiêu Chuẩn | G7: Common | H7: unreleased | I7: Car Defaults | J7: /Content/Vehicles/Lux_A/Mesh/Roof/SM_LuxA_Roof_Basic.uasset | L7: FALSE | M7: TRUE
A8: ccv_part_wheel_0001 | B8: ccv | C8: part | D8: Wheel Basic | E8: Mâm Tiêu Chuẩn | G8: Common | H8: unreleased | I8: Car Defaults | J8: /Content/Vehicles/Lux_A/Mesh/Wheel/SM_LuxA_Wheels_Basic.uasset | L8: FALSE | M8: TRUE
A9: ccv_part_ss_0001 | B9: ccv | C9: part | D9: Side Skirt Basic | E9: Ốp Sườn Tiêu Chuẩn | G9: Common | H9: unreleased | I9: Car Defaults | J9: /Content/Vehicles/Lux_A/Mesh/SideSkirt/SM_LuxA_SideBoard_Basic.uasset | L9: FALSE | M9: TRUE
A10: ccv_part_fb_0002 | B10: ccv | C10: part | D10: Front Bumper Sport | E10: Cản Trước Thể Thao | G10: UnCommon | H10: unreleased | I10: Post-Race Rewards | J10: /Content/Vehicles/Lux_A/Mesh/FrontBumper/SM_LuxA_FrontBumper_Sport.uasset | L10: FALSE | M10: TRUE
A11: ccv_part_rb_0002 | B11: ccv | C11: part | D11: Rear Bumper Sport | E11: Cản Sau Thể Thao | G11: UnCommon | H11: unreleased | I11: Post-Race Rewards | J11: /Content/Vehicles/Lux_A/Mesh/RearBumper/SM_LuxA_RearBumper_Sport.uasset | L11: FALSE | M11: TRUE
A12: ccv_part_sp_0002 | B12: ccv | C12: part | D12: Spoiler Sport | E12: Cánh Gió Thể Thao | G12: UnCommon | H12: unreleased | I12: Post-Race Rewards | J12: /Content/Vehicles/Lux_A/Mesh/Spoiler/SM_LuxA_Spoiler_Sport.uasset | L12: FALSE | M12: TRUE
A13: ccv_part_ro_0002 | B13: ccv | C13: part | D13: Roof Panel Sport | E13: Nóc Xe Thể Thao | G13: UnCommon | H13: unreleased | I13: Post-Race Rewards | J13: /Content/Vehicles/Lux_A/Mesh/Roof/SM_LuxA_Roof_Sport.uasset | L13: FALSE | M13: TRUE
A14: ccv_part_wheel_0002 | B14: ccv | C14: part | D14: Wheel Sport | E14: Mâm Thể Thao | G14: UnCommon | H14: unreleased | I14: Post-Race Rewards | J14: /Content/Vehicles/Lux_A/Mesh/Wheel/SM_LuxA_Wheel_Sport.uasset | L14: FALSE | M14: TRUE
A15: ccv_part_ss_0002 | B15: ccv | C15: part | D15: Side Skirt Sport | E15: Ốp Sườn Thể Thao | G15: UnCommon | H15: unreleased | I15: Post-Race Rewards | J15: /Content/Vehicles/Lux_A/Mesh/SideSkirt/SM_LuxA_SideBoard_Sport.uasset | L15: FALSE | M15: TRUE
A16: ccv_part_fb_0003 | B16: ccv | C16: part | D16: Front Bumper Luxury | E16: Cản Trước Cao Cấp | G16: Rare | H16: unreleased | I16: Post-Race Rewards | J16: /Content/Vehicles/Lux_A/Mesh/FrontBumper/SM_LuxA_FrontBumper_Luxury.uasset | L16: FALSE | M16: TRUE
... A57: ccv_part_ss_0009 | B57: ccv | C57: part | D57: Side Skirt Luxury | E57: Ốp Sườn Cao Cấp | G57: Rare | H57: unreleased | I57: Post-Race Rewards | J57: /Content/Vehicles/MercedesBenz_AMG_GT_R/Meshs/SideSkirt/SM_AMG_SideBoard_Luxury.uasset | L57: FALSE | M57: TRUE
A58: ccv_mat_body_0001 | B58: ccv | C58: mat_body | D58: Metallic Paint #1 | E58: Sơn Kim Loại #1 | G58: Common | H58: unreleased | I58: Post-Race Rewards | L58: FALSE | M58: TRUE
A59: ccv_mat_body_0002 | B59: ccv | C59: mat_body | D59: Metallic Paint #2 | E59: Sơn Kim Loại #2 | G59: Common | H59: unreleased | I59: Post-Race Rewards | L59: FALSE | M59: TRUE
A60: ccv_mat_body_0003 | B60: ccv | C60: mat_body | D60: Metallic Paint #3 | E60: Sơn Kim Loại #3 | G60: Common | H60: unreleased | I60: Post-Race Rewards | L60: FALSE | M60: TRUE
A61: ccv_mat_body_0004 | B61: ccv | C61: mat_body | D61: Glossy Paint #1 | E61: Sơn Bóng #1 | G61: Common | H61: unreleased | I61: Post-Race Rewards | L61: FALSE | M61: TRUE
A62: ccv_mat_body_0005 | B62: ccv | C62: mat_body | D62: Glossy Paint #2 | E62: Sơn Bóng #2 | G62: Common | H62: unreleased | I62: Post-Race Rewards | L62: FALSE | M62: TRUE
A63: ccv_mat_body_0006 | B63: ccv | C63: mat_body | D63: Glossy Paint #3 | E63: Sơn Bóng #3 | G63: Common | H63: unreleased | I63: Post-Race Rewards | L63: FALSE | M63: TRUE
A64: ccv_mat_body_0007 | B64: ccv | C64: mat_body | D64: Matte Paint #1 | E64: Sơn Nhẵn #1 | G64: Common | H64: unreleased | I64: Post-Race Rewards | L64: FALSE | M64: TRUE
A65: ccv_mat_body_0008 | B65: ccv | C65: mat_body | D65: Matte Paint #2 | E65: Sơn Nhẵn #2 | G65: Common | H65: unreleased | I65: Post-Race Rewards | L65: FALSE | M65: TRUE
A66: ccv_mat_body_0009 | B66: ccv | C66: mat_body | D66: Matte Paint #3 | E66: Sơn Nhẵn #3 | G66: Common | H66: unreleased | I66: Post-Race Rewards | L66: FALSE | M66: TRUE
A67: ccv_mat_body_0010 | B67: ccv | C67: mat_body | D67: Pearlescent Paint #1 | E67: Sơn Pearlescent #1 | G67: Common | H67: unreleased | I67: Post-Race Rewards | L67: FALSE | M67: TRUE
A68: ccv_mat_body_0011 | B68: ccv | C68: mat_body | D68: Pearlescent Paint #2 | E68: Sơn Pearlescent #2 | G68: Common | H68: unreleased | I68: Post-Race Rewards | L68: FALSE | M68: TRUE
A69: ccv_mat_body_0012 | B69: ccv | C69: mat_body | D69: Pearlescent Paint #3 | E69: Sơn Pearlescent #3 | G69: Common | H69: unreleased | I69: Post-Race Rewards | L69: FALSE | M69: TRUE
... A129: ccv_mat_wheel_0027 | B129: ccv | C129: mat_wheel | D129: Chameleon Wheel #3 | E129: Mâm Chameleon #3 | G129: UnCommon | H129: unreleased | I129: Post-Race Rewards | L129: FALSE | M129: TRUE
A130: ccv_dec_0001 | B130: ccv | C130: dec | D130: Stripe Line | E130: Sọc Stripe | G130: Common | H130: unreleased | I130: Post-Race Rewards | J130: - | K130: /Content/UI/Thumbnail_Folder/Customize_Skin/NoChange.uasset | L130: FALSE | M130: TRUE | N130: File Path nằm trong Sheet Visual_Decals
A131: ccv_dec_0002 | B131: ccv | C131: dec | D131: Logo Sponsorship | E131: Logo Tài Trợ | G131: Common | H131: unreleased | I131: Post-Race Rewards | J131: - | K131: /Content/UI/Thumbnail_Folder/Customize_Skin/NoChange.uasset | L131: FALSE | M131: TRUE | N131: File Path nằm trong Sheet Visual Decals
A132: ccv_dec_0003 | B132: ccv | C132: dec | D132: Graphic Theme | E132: Họa Tiết Graphic | G132: Common | H132: unreleased | I132: Post-Race Rewards | J132: - | K132: /Content/UI/Thumbnail_Folder/Customize_Skin/NoChange.uasset | L132: FALSE | M132: TRUE | N132: File Path nằm trong Sheet Visual Decals
A133: ccv_dec_0004 | B133: ccv | C133: dec | D133: Wraps | E133: Decal Phủ | G133: UnCommon | H133: unreleased | I133: Post-Race Rewards | J133: - | K133: /Content/UI/Thumbnail_Folder/Customize_Skin/NoChange.uasset | L133: FALSE | M133: TRUE | N133: File Path nằm trong Sheet Visual Decals
A134: ccv_dec_0005 | B134: ccv | C134: dec | D134: Stripe Line | E134: Sọc Stripe | G134: UnCommon | H134: unreleased | I134: Post-Race Rewards | J134: - | K134: /Content/UI/Thumbnail_Folder/Customize_Skin/NoChange.uasset | L134: FALSE | M134: TRUE | N134: File Path nằm trong Sheet Visual Decals
A135: ccv_dec_0006 | B135: ccv | C135: dec | D135: Logo Sponsorship | E135: Logo Tài Trợ | G135: Common | H135: unreleased | I135: Post-Race Rewards | J135: - | K135: /Content/UI/Thumbnail_Folder/Customize_Skin/NoChange.uasset | L135: FALSE | M135: TRUE | N135: File Path nằm trong Sheet Visual Decals
A136: ccv_dec_0007 | B136: ccv | C136: dec | D136: Graphic Theme | E136: Họa Tiết Graphic | G136: Common | H136: unreleased | I136: Post-Race Rewards | J136: - | K136: /Content/UI/Thumbnail_Folder/Customize_Skin/NoChange.uasset | L136: FALSE | M136: TRUE | N136: File Path nằm trong Sheet Visual Decals
A137: ccv_dec_0008 | B137: ccv | C137: dec | D137: Wraps | E137: Decal Phủ | G137: Common | H137: unreleased | I137: Post-Race Rewards | J137: - | K137: /Content/UI/Thumbnail_Folder/Customize_Skin/NoChange.uasset | L137: FALSE | M137: TRUE | N137: File Path nằm trong Sheet Visual Decals
A138: ccv_dec_0009 | B138: ccv | C138: dec | D138: Stripe Line | E138: Sọc Stripe | G138: UnCommon | H138: unreleased | I138: Post-Race Rewards | J138: - | K138: /Content/UI/Thumbnail_Folder/Customize_Skin/NoChange.uasset | L138: FALSE | M138: TRUE | N138: File Path nằm trong Sheet Visual Decals
A139: ccv_dec_0010 | B139: ccv | C139: dec | D139: Logo Sponsorship | E139: Logo Tài Trợ | G139: UnCommon | H139: unreleased | I139: Post-Race Rewards | J139: - | K139: /Content/UI/Thumbnail_Folder/Customize_Skin/NoChange.uasset | L139: FALSE | M139: TRUE | N139: File Path nằm trong Sheet Visual Decals
...

Sheet VISUAL_DECALS
A1: MaterialDecalName | B1: Decal | C1: car | D1: body_materialpath | E1: frontbumper | F1: frontBump_materialpath | G1: rearbumper | H1: rearBump_materialpath | I1: sideBoard | J1: sideBoard_materialPath | K1: roof | L1: roof_materialPath | M1: spoiler | N1: spoiler_materialPath
A2: MI_LuxA_RacingstripesLines_Basic | B2: ccv_dec_0001 | C2: =IFERROR(VLOOKUP(B2,ITEM_VISUAL!A:D,4,0),"?") -> car_vin_1 | D2: /Content/Vehicles/Lux_A/Materials/Paints/Decal/MI_LuxA_RacingstripesLines_Basic.uasset | E2: ccv_part_fb_0001 | F2: /Content/Vehicles/Lux_A/Materials/Paints/Decal/MI_LuxA_RacingstripesLines_Basic.uasset | G2: ccv_part_rb_0001 | H2: /Content/Vehicles/Lux_A/Materials/Paints/Decal/MI_LuxA_RacingstripesLines_Basic.uasset | I2: ccv_part_sb_0001 | J2: /Content/Vehicles/Lux_A/Materials/Paints/Decal/MI_LuxA_RacingstripesLines_Basic.uasset | K2: ccv_part_ro_0001 | L2: /Content/Vehicles/Lux_A/Materials/Paints/Decal/MI_LuxA_RacingstripesLines_Basic.uasset | M2: ccv_part_sp_0001 | N2: /Content/Vehicles/Lux_A/Materials/Paints/Decal/MI_LuxA_RacingstripesLines_Basic.uasset
A3: MI_LuxA_RacingstripesLines_Sport | B3: ccv_dec_0001 | C3: =IFERROR(VLOOKUP(B3,ITEM_VISUAL!A:D,4,0),"?") -> car_vin_1 | D3: /Content/Vehicles/Lux_A/Materials/Paints/Decal/MI_LuxA_RacingstripesLines_Sport.uasset | E3: ccv_part_fb_0002 | F3: /Content/Vehicles/Lux_A/Materials/Paints/Decal/MI_LuxA_RacingstripesLines_Sport.uasset | G3: ccv_part_rb_0002 | H3: /Content/Vehicles/Lux_A/Materials/Paints/Decal/MI_LuxA_RacingstripesLines_Sport.uasset | I3: ccv_part_sb_0002 | J3: /Content/Vehicles/Lux_A/Materials/Paints/Decal/MI_LuxA_RacingstripesLines_Sport.uasset | K3: ccv_part_ro_0002 | L3: /Content/Vehicles/Lux_A/Materials/Paints/Decal/MI_LuxA_RacingstripesLines_Sport.uasset | M3: ccv_part_sp_0002 | N3: /Content/Vehicles/Lux_A/Materials/Paints/Decal/MI_LuxA_RacingstripesLines_Sport.uasset
A4: MI_LuxA_RacingstripesLines_Luxury | B4: ccv_dec_0001 | C4: =IFERROR(VLOOKUP(B4,ITEM_VISUAL!A:D,4,0),"?") -> car_vin_1 | D4: /Content/Vehicles/Lux_A/Materials/Paints/Decal/MI_LuxA_RacingstripesLines_Luxury.uasset | E4: ccv_part_fb_0003 | F4: /Content/Vehicles/Lux_A/Materials/Paints/Decal/MI_LuxA_RacingstripesLines_Luxury.uasset | G4: ccv_part_rb_0003 | H4: /Content/Vehicles/Lux_A/Materials/Paints/Decal/MI_LuxA_RacingstripesLines_Luxury.uasset | I4: ccv_part_sb_0003 | J4: /Content/Vehicles/Lux_A/Materials/Paints/Decal/MI_LuxA_RacingstripesLines_Luxury.uasset | K4: ccv_part_ro_0003 | L4: /Content/Vehicles/Lux_A/Materials/Paints/Decal/MI_LuxA_RacingstripesLines_Luxury.uasset | M4: ccv_part_sp_0003 | N4: /Content/Vehicles/Lux_A/Materials/Paints/Decal/MI_LuxA_RacingstripesLines_Luxury.uasset
A5: MI_LuxA_LOGOSSPONSORSHIP_Basic | B5: ccv_dec_0002 | C5: =IFERROR(VLOOKUP(B5,ITEM_VISUAL!A:D,4,0),"?") -> car_vin_1 | D5: /Content/Vehicles/Lux_A/Materials/Paints/Decal/MI_LuxA_LOGOSSPONSORSHIP_Basic.uasset | E5: ccv_part_fb_0001 | F5: /Content/Vehicles/Lux_A/Materials/Paints/Decal/MI_LuxA_LOGOSSPONSORSHIP_Basic.uasset | G5: ccv_part_rb_0001 | H5: /Content/Vehicles/Lux_A/Materials/Paints/Decal/MI_LuxA_LOGOSSPONSORSHIP_Basic.uasset | I5: ccv_part_sb_0001 | J5: /Content/Vehicles/Lux_A/Materials/Paints/Decal/MI_LuxA_LOGOSSPONSORSHIP_Basic.uasset | K5: ccv_part_ro_0001 | L5: /Content/Vehicles/Lux_A/Materials/Paints/Decal/MI_LuxA_LOGOSSPONSORSHIP_Basic.uasset | M5: ccv_part_sp_0001 | N5: /Content/Vehicles/Lux_A/Materials/Paints/Decal/MI_LuxA_LOGOSSPONSORSHIP_Basic.uasset
A6: MI_LuxA_LOGOSSPONSORSHIP_Sport | B6: ccv_dec_0002 | C6: =IFERROR(VLOOKUP(B6,ITEM_VISUAL!A:D,4,0),"?") -> car_vin_1 | D6: /Content/Vehicles/Lux_A/Materials/Paints/Decal/MI_LuxA_LOGOSSPONSORSHIP_Sport.uasset | E6: ccv_part_fb_0002 | F6: /Content/Vehicles/Lux_A/Materials/Paints/Decal/MI_LuxA_LOGOSSPONSORSHIP_Sport.uasset | G6: ccv_part_rb_0002 | H6: /Content/Vehicles/Lux_A/Materials/Paints/Decal/MI_LuxA_LOGOSSPONSORSHIP_Sport.uasset | I6: ccv_part_sb_0002 | J6: /Content/Vehicles/Lux_A/Materials/Paints/Decal/MI_LuxA_LOGOSSPONSORSHIP_Sport.uasset | K6: ccv_part_ro_0002 | L6: /Content/Vehicles/Lux_A/Materials/Paints/Decal/MI_LuxA_LOGOSSPONSORSHIP_Sport.uasset | M6: ccv_part_sp_0002 | N6: /Content/Vehicles/Lux_A/Materials/Paints/Decal/MI_LuxA_LOGOSSPONSORSHIP_Sport.uasset
A7: MI_LuxA_LOGOSSPONSORSHIP_Luxury | B7: ccv_dec_0002 | C7: =IFERROR(VLOOKUP(B7,ITEM_VISUAL!A:D,4,0),"?") -> car_vin_1 | D7: /Content/Vehicles/Lux_A/Materials/Paints/Decal/MI_LuxA_LOGOSSPONSORSHIP_Luxury.uasset | E7: ccv_part_fb_0003 | F7: /Content/Vehicles/Lux_A/Materials/Paints/Decal/MI_LuxA_LOGOSSPONSORSHIP_Luxury.uasset | G7: ccv_part_rb_0003 | H7: /Content/Vehicles/Lux_A/Materials/Paints/Decal/MI_LuxA_LOGOSSPONSORSHIP_Luxury.uasset | I7: ccv_part_sb_0003 | J7: /Content/Vehicles/Lux_A/Materials/Paints/Decal/MI_LuxA_LOGOSSPONSORSHIP_Luxury.uasset | K7: ccv_part_ro_0003 | L7: /Content/Vehicles/Lux_A/Materials/Paints/Decal/MI_LuxA_LOGOSSPONSORSHIP_Luxury.uasset | M7: ccv_part_sp_0003 | N7: /Content/Vehicles/Lux_A/Materials/Paints/Decal/MI_LuxA_LOGOSSPONSORSHIP_Luxury.uasset
A8: MI_LuxA_GRAPHICSTHEMES_Basic | B8: ccv_dec_0003 | C8: =IFERROR(VLOOKUP(B8,ITEM_VISUAL!A:D,4,0),"?") -> car_vin_1 | D8: /Content/Vehicles/Lux_A/Materials/Paints/Decal/MI_LuxA_GRAPHICSTHEMES_Basic.uasset | E8: ccv_part_fb_0001 | F8: /Content/Vehicles/Lux_A/Materials/Paints/Decal/MI_LuxA_GRAPHICSTHEMES_Basic.uasset | G8: ccv_part_rb_0001 | H8: /Content/Vehicles/Lux_A/Materials/Paints/Decal/MI_LuxA_GRAPHICSTHEMES_Basic.uasset | I8: ccv_part_sb_0001 | J8: /Content/Vehicles/Lux_A/Materials/Paints/Decal/MI_LuxA_GRAPHICSTHEMES_Basic.uasset | K8: ccv_part_ro_0001 | L8: /Content/Vehicles/Lux_A/Materials/Paints/Decal/MI_LuxA_GRAPHICSTHEMES_Basic.uasset | M8: ccv_part_sp_0001 | N8: /Content/Vehicles/Lux_A/Materials/Paints/Decal/MI_LuxA_GRAPHICSTHEMES_Basic.uasset
A9: MI_LuxA_GRAPHICSTHEMES_Sport | B9: ccv_dec_0003 | C9: =IFERROR(VLOOKUP(B9,ITEM_VISUAL!A:D,4,0),"?") -> car_vin_1 | D9: /Content/Vehicles/Lux_A/Materials/Paints/Decal/MI_LuxA_GRAPHICSTHEMES_Sport.uasset | E9: ccv_part_fb_0002 | F9: /Content/Vehicles/Lux_A/Materials/Paints/Decal/MI_LuxA_GRAPHICSTHEMES_Sport.uasset | G9: ccv_part_rb_0002 | H9: /Content/Vehicles/Lux_A/Materials/Paints/Decal/MI_LuxA_GRAPHICSTHEMES_Sport.uasset | I9: ccv_part_sb_0002 | J9: /Content/Vehicles/Lux_A/Materials/Paints/Decal/MI_LuxA_GRAPHICSTHEMES_Sport.uasset | K9: ccv_part_ro_0002 | L9: /Content/Vehicles/Lux_A/Materials/Paints/Decal/MI_LuxA_GRAPHICSTHEMES_Sport.uasset | M9: ccv_part_sp_0002 | N9: /Content/Vehicles/Lux_A/Materials/Paints/Decal/MI_LuxA_GRAPHICSTHEMES_Sport.uasset
A10: MI_LuxA_GRAPHICSTHEMES_Luxury | B10: ccv_dec_0003 | C10: =IFERROR(VLOOKUP(B10,ITEM_VISUAL!A:D,4,0),"?") -> car_vin_1 | D10: /Content/Vehicles/Lux_A/Materials/Paints/Decal/MI_LuxA_GRAPHICSTHEMES_Luxury.uasset | E10: ccv_part_fb_0003 | F10: /Content/Vehicles/Lux_A/Materials/Paints/Decal/MI_LuxA_GRAPHICSTHEMES_Luxury.uasset | G10: ccv_part_rb_0003 | H10: /Content/Vehicles/Lux_A/Materials/Paints/Decal/MI_LuxA_GRAPHICSTHEMES_Luxury.uasset | I10: ccv_part_sb_0003 | J10: /Content/Vehicles/Lux_A/Materials/Paints/Decal/MI_LuxA_GRAPHICSTHEMES_Luxury.uasset | K10: ccv_part_ro_0003 | L10: /Content/Vehicles/Lux_A/Materials/Paints/Decal/MI_LuxA_GRAPHICSTHEMES_Luxury.uasset | M10: ccv_part_sp_0003 | N10: /Content/Vehicles/Lux_A/Materials/Paints/Decal/MI_LuxA_GRAPHICSTHEMES_Luxury.uasset
A11: MI_LuxA_Carpaint_Decal_Wraps_Basic | B11: ccv_dec_0004 | C11: =IFERROR(VLOOKUP(B11,ITEM_VISUAL!A:D,4,0),"?") -> car_vin_1 | D11: /Content/Vehicles/Lux_A/Materials/Paints/Decal/MI_LuxA_Carpaint_Decal_Wraps_Basic.uasset | E11: ccv_part_fb_0001 | F11: /Content/Vehicles/Lux_A/Materials/Paints/Decal/MI_LuxA_Carpaint_Decal_Wraps_Basic.uasset | G11: ccv_part_rb_0001 | H11: /Content/Vehicles/Lux_A/Materials/Paints/Decal/MI_LuxA_Carpaint_Decal_Wraps_Basic.uasset | I11: ccv_part_sb_0001 | J11: /Content/Vehicles/Lux_A/Materials/Paints/Decal/MI_LuxA_Carpaint_Decal_Wraps_Basic.uasset | K11: ccv_part_ro_0001 | L11: /Content/Vehicles/Lux_A/Materials/Paints/Decal/MI_LuxA_Carpaint_Decal_Wraps_Basic.uasset | M11: ccv_part_sp_0001 | N11: /Content/Vehicles/Lux_A/Materials/Paints/Decal/MI_LuxA_Carpaint_Decal_Wraps_Basic.uasset
A12: MI_LuxA_Carpaint_Decal_Wraps_Sport | B12: ccv_dec_0004 | C12: =IFERROR(VLOOKUP(B12,ITEM_VISUAL!A:D,4,0),"?") -> car_vin_1 | D12: /Content/Vehicles/Lux_A/Materials/Paints/Decal/MI_LuxA_Carpaint_Decal_Wraps_Sport.uasset | E12: ccv_part_fb_0002 | F12: /Content/Vehicles/Lux_A/Materials/Paints/Decal/MI_LuxA_Carpaint_Decal_Wraps_Sport.uasset | G12: ccv_part_rb_0002 | H12: /Content/Vehicles/Lux_A/Materials/Paints/Decal/MI_LuxA_Carpaint_Decal_Wraps_Sport.uasset | I12: ccv_part_sb_0002 | J12: /Content/Vehicles/Lux_A/Materials/Paints/Decal/MI_LuxA_Carpaint_Decal_Wraps_Sport.uasset | K12: ccv_part_ro_0002 | L12: /Content/Vehicles/Lux_A/Materials/Paints/Decal/MI_LuxA_Carpaint_Decal_Wraps_Sport.uasset | M12: ccv_part_sp_0002 | N12: /Content/Vehicles/Lux_A/Materials/Paints/Decal/MI_LuxA_Carpaint_Decal_Wraps_Sport.uasset
A13: MI_LuxA_Carpaint_Decal_Wraps_Luxury | B13: ccv_dec_0004 | C13: =IFERROR(VLOOKUP(B13,ITEM_VISUAL!A:D,4,0),"?") -> car_vin_1 | D13: /Content/Vehicles/Lux_A/Materials/Paints/Decal/MI_LuxA_Carpaint_Decal_Wraps_Luxury.uasset | E13: ccv_part_fb_0003 | F13: /Content/Vehicles/Lux_A/Materials/Paints/Decal/MI_LuxA_Carpaint_Decal_Wraps_Luxury.uasset | G13: ccv_part_rb_0003 | H13: /Content/Vehicles/Lux_A/Materials/Paints/Decal/MI_LuxA_Carpaint_Decal_Wraps_Luxury.uasset | I13: ccv_part_sb_0003 | J13: /Content/Vehicles/Lux_A/Materials/Paints/Decal/MI_LuxA_Carpaint_Decal_Wraps_Luxury.uasset | K13: ccv_part_ro_0003 | L13: /Content/Vehicles/Lux_A/Materials/Paints/Decal/MI_LuxA_Carpaint_Decal_Wraps_Luxury.uasset | M13: ccv_part_sp_0003 | N13: /Content/Vehicles/Lux_A/Materials/Paints/Decal/MI_LuxA_Carpaint_Decal_Wraps_Luxury.uasset
... A37: MI_AMG_Decal_Wraps_Luxury | B37: ccv_dec_0012 | C37: =IFERROR(VLOOKUP(B37,ITEM_VISUAL!A:D,4,0),"?") -> car_mer_1 | D37: /Content/Vehicles/MercedesBenz_AMG_GT_R/Materials/Paints/Decal/MI_AMG_Decal_Wraps_Luxury.uasset | E37: ccv_part_fb_0009 | F37: /Content/Vehicles/MercedesBenz_AMG_GT_R/Materials/Paints/Decal/MI_AMG_Decal_Wraps_Luxury.uasset | G37: ccv_part_rb_0009 | H37: /Content/Vehicles/MercedesBenz_AMG_GT_R/Materials/Paints/Decal/MI_AMG_Decal_Wraps_Luxury.uasset | I37: ccv_part_sb_0009 | J37: /Content/Vehicles/MercedesBenz_AMG_GT_R/Materials/Paints/Decal/MI_AMG_Decal_Wraps_Luxury.uasset | K37: ccv_part_ro_0009 | L37: /Content/Vehicles/MercedesBenz_AMG_GT_R/Materials/Paints/Decal/MI_AMG_Decal_Wraps_Luxury.uasset | M37: ccv_part_sp_0009 | N37: /Content/Vehicles/MercedesBenz_AMG_GT_R/Materials/Paints/Decal/MI_AMG_Decal_Wraps_Luxury.uasset
C990: car_vin1

Sheet ITEM_VISUAL
A1: catalog_id | B1: subcategory | C1: slot | D1: car_id | E1: display_name_EN | F1: display_name_VN | G1: rarity | H1: status | I1: unlock_source | J1: file_path | K1: icon_path | L1: notes
E2: ← VLOOKUP → CATALOG_MASTER | F2: ← VLOOKUP → CATALOG_MASTER | G2: ← VLOOKUP → CATALOG_MASTER | H2: ← VLOOKUP → CATALOG_MASTER | I2: ← VLOOKUP → CATALOG_MASTER | J2: ← VLOOKUP → CATALOG_MASTER | K2: ← VLOOKUP → CATALOG_MASTER
A3: ccv_part_fb_0001 | B3: part | C3: Front Bumper | D3: car_vin_1 | E3: =IFERROR(VLOOKUP(A3,ITEM_MASTER!$A:$E,4,0),"?") -> Front Bumper Basic | F3: =IFERROR(VLOOKUP(A3,ITEM_MASTER!$A:$E,5,0),"?") -> Cản Trước Tiêu Chuẩn | G3: =IFERROR(VLOOKUP($A3,ITEM_MASTER!$A:$I,7,0),"?") -> Common | H3: =IFERROR(VLOOKUP($A3,ITEM_MASTER!$A:$I,8,0),"?") -> unreleased | I3: =IFERROR(VLOOKUP($A3,ITEM_MASTER!$A:$I,9,0),"?") -> Car Defaults | J3: =IFERROR(VLOOKUP($A3,ITEM_MASTER!$A:$J,10,0),"?") -> /Content/Vehicles/Lux_A/Mesh/FrontBumper/SM_LuxA_FrontBumper_Basic.uasset | K3: =IFERROR(VLOOKUP($A3,ITEM_MASTER!$A:$K,11,0),"?") -> path_i | L3: =IFERROR(VLOOKUP($A3,ITEM_MASTER!$A:$N,12,0),"?") -> FALSE
A4: ccv_part_rb_0001 | B4: part | C4: Rear Bumper | D4: car_vin_1 | E4: =IFERROR(VLOOKUP(A4,ITEM_MASTER!$A:$E,4,0),"?") -> Rear Bumper Basic | F4: =IFERROR(VLOOKUP(A4,ITEM_MASTER!$A:$E,5,0),"?") -> Cản Sau Tiêu Chuẩn | G4: =IFERROR(VLOOKUP($A4,ITEM_MASTER!$A:$I,7,0),"?") -> Common | H4: =IFERROR(VLOOKUP($A4,ITEM_MASTER!$A:$I,8,0),"?") -> unreleased | I4: =IFERROR(VLOOKUP($A4,ITEM_MASTER!$A:$I,9,0),"?") -> Car Defaults | J4: =IFERROR(VLOOKUP($A4,ITEM_MASTER!$A:$J,10,0),"?") -> /Content/Vehicles/Lux_A/Mesh/RearBumper/SM_LuxA_RearBumper_Basic.uasset | K4: =IFERROR(VLOOKUP($A4,ITEM_MASTER!$A:$K,11,0),"?") | L4: =IFERROR(VLOOKUP($A4,ITEM_MASTER!$A:$N,12,0),"?") -> FALSE
A5: ccv_part_sp_0001 | B5: part | C5: Spoiler | D5: car_vin_1 | E5: =IFERROR(VLOOKUP(A5,ITEM_MASTER!$A:$E,4,0),"?") -> Spoiler Basic | F5: =IFERROR(VLOOKUP(A5,ITEM_MASTER!$A:$E,5,0),"?") -> Cánh Gió Tiêu Chuẩn | G5: =IFERROR(VLOOKUP($A5,ITEM_MASTER!$A:$I,7,0),"?") -> Common | H5: =IFERROR(VLOOKUP($A5,ITEM_MASTER!$A:$I,8,0),"?") -> unreleased | I5: =IFERROR(VLOOKUP($A5,ITEM_MASTER!$A:$I,9,0),"?") -> Car Defaults | J5: =IFERROR(VLOOKUP($A5,ITEM_MASTER!$A:$J,10,0),"?") -> /Content/Vehicles/Lux_A/Mesh/Spoiler/SM_LuxA_Spoiler_Basic.uasset | K5: =IFERROR(VLOOKUP($A5,ITEM_MASTER!$A:$K,11,0),"?") | L5: =IFERROR(VLOOKUP($A5,ITEM_MASTER!$A:$N,12,0),"?") -> FALSE
A6: ccv_part_ro_0001 | B6: part | C6: Roof | D6: car_vin_1 | E6: =IFERROR(VLOOKUP(A6,ITEM_MASTER!$A:$E,4,0),"?") -> Roof Panel Basic | F6: =IFERROR(VLOOKUP(A6,ITEM_MASTER!$A:$E,5,0),"?") -> Nóc Xe Tiêu Chuẩn | G6: =IFERROR(VLOOKUP($A6,ITEM_MASTER!$A:$I,7,0),"?") -> Common | H6: =IFERROR(VLOOKUP($A6,ITEM_MASTER!$A:$I,8,0),"?") -> unreleased | I6: =IFERROR(VLOOKUP($A6,ITEM_MASTER!$A:$I,9,0),"?") -> Car Defaults | J6: =IFERROR(VLOOKUP($A6,ITEM_MASTER!$A:$J,10,0),"?") -> /Content/Vehicles/Lux_A/Mesh/Roof/SM_LuxA_Roof_Basic.uasset | K6: =IFERROR(VLOOKUP($A6,ITEM_MASTER!$A:$K,11,0),"?") | L6: =IFERROR(VLOOKUP($A6,ITEM_MASTER!$A:$N,12,0),"?") -> FALSE
A7: ccv_part_wheel_0001 | B7: part | C7: Wheel | D7: car_vin_1 | E7: =IFERROR(VLOOKUP(A7,ITEM_MASTER!$A:$E,4,0),"?") -> Wheel Basic | F7: =IFERROR(VLOOKUP(A7,ITEM_MASTER!$A:$E,5,0),"?") -> Mâm Tiêu Chuẩn | G7: =IFERROR(VLOOKUP($A7,ITEM_MASTER!$A:$I,7,0),"?") -> Common | H7: =IFERROR(VLOOKUP($A7,ITEM_MASTER!$A:$I,8,0),"?") -> unreleased | I7: =IFERROR(VLOOKUP($A7,ITEM_MASTER!$A:$I,9,0),"?") -> Car Defaults | J7: =IFERROR(VLOOKUP($A7,ITEM_MASTER!$A:$J,10,0),"?") -> /Content/Vehicles/Lux_A/Mesh/Wheel/SM_LuxA_Wheels_Basic.uasset | K7: =IFERROR(VLOOKUP($A7,ITEM_MASTER!$A:$K,11,0),"?") | L7: =IFERROR(VLOOKUP($A7,ITEM_MASTER!$A:$N,12,0),"?") -> FALSE
A8: ccv_part_ss_0001 | B8: part | C8: Side Skirt | D8: car_vin_1 | E8: =IFERROR(VLOOKUP(A8,ITEM_MASTER!$A:$E,4,0),"?") -> Side Skirt Basic | F8: =IFERROR(VLOOKUP(A8,ITEM_MASTER!$A:$E,5,0),"?") -> Ốp Sườn Tiêu Chuẩn | G8: =IFERROR(VLOOKUP($A8,ITEM_MASTER!$A:$I,7,0),"?") -> Common | H8: =IFERROR(VLOOKUP($A8,ITEM_MASTER!$A:$I,8,0),"?") -> unreleased | I8: =IFERROR(VLOOKUP($A8,ITEM_MASTER!$A:$I,9,0),"?") -> Car Defaults | J8: =IFERROR(VLOOKUP($A8,ITEM_MASTER!$A:$J,10,0),"?") -> /Content/Vehicles/Lux_A/Mesh/SideSkirt/SM_LuxA_SideBoard_Basic.uasset | K8: =IFERROR(VLOOKUP($A8,ITEM_MASTER!$A:$K,11,0),"?") | L8: =IFERROR(VLOOKUP($A8,ITEM_MASTER!$A:$N,12,0),"?") -> FALSE
A9: ccv_part_fb_0002 | B9: part | C9: Front Bumper | D9: car_vin_1 | E9: =IFERROR(VLOOKUP(A9,ITEM_MASTER!$A:$E,4,0),"?") -> Front Bumper Sport | F9: =IFERROR(VLOOKUP(A9,ITEM_MASTER!$A:$E,5,0),"?") -> Cản Trước Thể Thao | G9: =IFERROR(VLOOKUP($A9,ITEM_MASTER!$A:$I,7,0),"?") -> UnCommon | H9: =IFERROR(VLOOKUP($A9,ITEM_MASTER!$A:$I,8,0),"?") -> unreleased | I9: =IFERROR(VLOOKUP($A9,ITEM_MASTER!$A:$I,9,0),"?") -> Post-Race Rewards | J9: =IFERROR(VLOOKUP($A9,ITEM_MASTER!$A:$J,10,0),"?") -> /Content/Vehicles/Lux_A/Mesh/FrontBumper/SM_LuxA_FrontBumper_Sport.uasset | K9: =IFERROR(VLOOKUP($A9,ITEM_MASTER!$A:$K,11,0),"?") | L9: =IFERROR(VLOOKUP($A9,ITEM_MASTER!$A:$N,12,0),"?") -> FALSE
A10: ccv_part_rb_0002 | B10: part | C10: Rear Bumper | D10: car_vin_1 | E10: =IFERROR(VLOOKUP(A10,ITEM_MASTER!$A:$E,4,0),"?") -> Rear Bumper Sport | F10: =IFERROR(VLOOKUP(A10,ITEM_MASTER!$A:$E,5,0),"?") -> Cản Sau Thể Thao | G10: =IFERROR(VLOOKUP($A10,ITEM_MASTER!$A:$I,7,0),"?") -> UnCommon | H10: =IFERROR(VLOOKUP($A10,ITEM_MASTER!$A:$I,8,0),"?") -> unreleased | I10: =IFERROR(VLOOKUP($A10,ITEM_MASTER!$A:$I,9,0),"?") -> Post-Race Rewards | J10: =IFERROR(VLOOKUP($A10,ITEM_MASTER!$A:$J,10,0),"?") -> /Content/Vehicles/Lux_A/Mesh/RearBumper/SM_LuxA_RearBumper_Sport.uasset | K10: =IFERROR(VLOOKUP($A10,ITEM_MASTER!$A:$K,11,0),"?") | L10: =IFERROR(VLOOKUP($A10,ITEM_MASTER!$A:$N,12,0),"?") -> FALSE
A11: ccv_part_sp_0002 | B11: part | C11: Spoiler | D11: car_vin_1 | E11: =IFERROR(VLOOKUP(A11,ITEM_MASTER!$A:$E,4,0),"?") -> Spoiler Sport | F11: =IFERROR(VLOOKUP(A11,ITEM_MASTER!$A:$E,5,0),"?") -> Cánh Gió Thể Thao | G11: =IFERROR(VLOOKUP($A11,ITEM_MASTER!$A:$I,7,0),"?") -> UnCommon | H11: =IFERROR(VLOOKUP($A11,ITEM_MASTER!$A:$I,8,0),"?") -> unreleased | I11: =IFERROR(VLOOKUP($A11,ITEM_MASTER!$A:$I,9,0),"?") -> Post-Race Rewards | J11: =IFERROR(VLOOKUP($A11,ITEM_MASTER!$A:$J,10,0),"?") -> /Content/Vehicles/Lux_A/Mesh/Spoiler/SM_LuxA_Spoiler_Sport.uasset | K11: =IFERROR(VLOOKUP($A11,ITEM_MASTER!$A:$K,11,0),"?") | L11: =IFERROR(VLOOKUP($A11,ITEM_MASTER!$A:$N,12,0),"?") -> FALSE
A12: ccv_part_ro_0002 | B12: part | C12: Roof | D12: car_vin_1 | E12: =IFERROR(VLOOKUP(A12,ITEM_MASTER!$A:$E,4,0),"?") -> Roof Panel Sport | F12: =IFERROR(VLOOKUP(A12,ITEM_MASTER!$A:$E,5,0),"?") -> Nóc Xe Thể Thao | G12: =IFERROR(VLOOKUP($A12,ITEM_MASTER!$A:$I,7,0),"?") -> UnCommon | H12: =IFERROR(VLOOKUP($A12,ITEM_MASTER!$A:$I,8,0),"?") -> unreleased | I12: =IFERROR(VLOOKUP($A12,ITEM_MASTER!$A:$I,9,0),"?") -> Post-Race Rewards | J12: =IFERROR(VLOOKUP($A12,ITEM_MASTER!$A:$J,10,0),"?") -> /Content/Vehicles/Lux_A/Mesh/Roof/SM_LuxA_Roof_Sport.uasset | K12: =IFERROR(VLOOKUP($A12,ITEM_MASTER!$A:$K,11,0),"?") | L12: =IFERROR(VLOOKUP($A12,ITEM_MASTER!$A:$N,12,0),"?") -> FALSE
A13: ccv_part_wheel_0002 | B13: part | C13: Wheel | D13: car_vin_1 | E13: =IFERROR(VLOOKUP(A13,ITEM_MASTER!$A:$E,4,0),"?") -> Wheel Sport | F13: =IFERROR(VLOOKUP(A13,ITEM_MASTER!$A:$E,5,0),"?") -> Mâm Thể Thao | G13: =IFERROR(VLOOKUP($A13,ITEM_MASTER!$A:$I,7,0),"?") -> UnCommon | H13: =IFERROR(VLOOKUP($A13,ITEM_MASTER!$A:$I,8,0),"?") -> unreleased | I13: =IFERROR(VLOOKUP($A13,ITEM_MASTER!$A:$I,9,0),"?") -> Post-Race Rewards | J13: =IFERROR(VLOOKUP($A13,ITEM_MASTER!$A:$J,10,0),"?") -> /Content/Vehicles/Lux_A/Mesh/Wheel/SM_LuxA_Wheel_Sport.uasset | K13: =IFERROR(VLOOKUP($A13,ITEM_MASTER!$A:$K,11,0),"?") | L13: =IFERROR(VLOOKUP($A13,ITEM_MASTER!$A:$N,12,0),"?") -> FALSE
A14: ccv_part_ss_0002 | B14: part | C14: Side Skirt | D14: car_vin_1 | E14: =IFERROR(VLOOKUP(A14,ITEM_MASTER!$A:$E,4,0),"?") -> Side Skirt Sport | F14: =IFERROR(VLOOKUP(A14,ITEM_MASTER!$A:$E,5,0),"?") -> Ốp Sườn Thể Thao | G14: =IFERROR(VLOOKUP($A14,ITEM_MASTER!$A:$I,7,0),"?") -> UnCommon | H14: =IFERROR(VLOOKUP($A14,ITEM_MASTER!$A:$I,8,0),"?") -> unreleased | I14: =IFERROR(VLOOKUP($A14,ITEM_MASTER!$A:$I,9,0),"?") -> Post-Race Rewards | J14: =IFERROR(VLOOKUP($A14,ITEM_MASTER!$A:$J,10,0),"?") -> /Content/Vehicles/Lux_A/Mesh/SideSkirt/SM_LuxA_SideBoard_Sport.uasset | K14: =IFERROR(VLOOKUP($A14,ITEM_MASTER!$A:$K,11,0),"?") | L14: =IFERROR(VLOOKUP($A14,ITEM_MASTER!$A:$N,12,0),"?") -> FALSE
... A31: ccv_part_wheel_0005 | B31: part | C31: Wheel | D31: car_vin_2 | E31: =IFERROR(VLOOKUP(A31,ITEM_MASTER!$A:$E,4,0),"?") -> Wheel Sport | F31: =IFERROR(VLOOKUP(A31,ITEM_MASTER!$A:$E,5,0),"?") -> Mâm Thể Thao | G31: =IFERROR(VLOOKUP($A31,ITEM_MASTER!$A:$I,7,0),"?") -> UnCommon | H31: =IFERROR(VLOOKUP($A31,ITEM_MASTER!$A:$I,8,0),"?") -> unreleased | I31: =IFERROR(VLOOKUP($A31,ITEM_MASTER!$A:$I,9,0),"?") -> Post-Race Rewards | J31: =IFERROR(VLOOKUP($A31,ITEM_MASTER!$A:$J,10,0),"?") -> /Content/Vehicles/VF8/Mesh/Wheel/SM_VF8_Wheels_Sport.uasset | K31: =IFERROR(VLOOKUP($A31,ITEM_MASTER!$A:$K,11,0),"?") | L31: =IFERROR(VLOOKUP($A31,ITEM_MASTER!$A:$N,12,0),"?") -> FALSE
A32: ccv_part_ss_0005 | B32: =MID(A32,FIND("_",A32) + 1,FIND(CHAR(160),SUBSTITUTE(A32,"_",CHAR(160),2)) - 1 - (FIND("_",A32))) -> part | C32: Side Skirt | D32: car_vin_2 | E32: =IFERROR(VLOOKUP(A32,ITEM_MASTER!$A:$E,4,0),"?") -> Side Skirt Sport | F32: =IFERROR(VLOOKUP(A32,ITEM_MASTER!$A:$E,5,0),"?") -> Ốp Sườn Thể Thao | G32: =IFERROR(VLOOKUP($A32,ITEM_MASTER!$A:$I,7,0),"?") -> UnCommon | H32: =IFERROR(VLOOKUP($A32,ITEM_MASTER!$A:$I,8,0),"?") -> unreleased | I32: =IFERROR(VLOOKUP($A32,ITEM_MASTER!$A:$I,9,0),"?") -> Post-Race Rewards | J32: =IFERROR(VLOOKUP($A32,ITEM_MASTER!$A:$J,10,0),"?") -> /Content/Vehicles/VF8/Mesh/SideSkirt/SM_VF8_SideBoard_Sport.uasset | K32: =IFERROR(VLOOKUP($A32,ITEM_MASTER!$A:$K,11,0),"?") | L32: =IFERROR(VLOOKUP($A32,ITEM_MASTER!$A:$N,12,0),"?") -> FALSE
A33: ccv_part_fb_0006 | B33: =MID(A33,FIND("_",A33) + 1,FIND(CHAR(160),SUBSTITUTE(A33,"_",CHAR(160),2)) - 1 - (FIND("_",A33))) -> part | C33: Front Bumper | D33: car_vin_2 | E33: =IFERROR(VLOOKUP(A33,ITEM_MASTER!$A:$E,4,0),"?") -> Front Bumper Luxury | F33: =IFERROR(VLOOKUP(A33,ITEM_MASTER!$A:$E,5,0),"?") -> Cản Trước Cao Cấp | G33: =IFERROR(VLOOKUP($A33,ITEM_MASTER!$A:$I,7,0),"?") -> Rare | H33: =IFERROR(VLOOKUP($A33,ITEM_MASTER!$A:$I,8,0),"?") -> unreleased | I33: =IFERROR(VLOOKUP($A33,ITEM_MASTER!$A:$I,9,0),"?") -> Post-Race Rewards | J33: =IFERROR(VLOOKUP($A33,ITEM_MASTER!$A:$J,10,0),"?") -> /Content/Vehicles/VF8/Mesh/FrontBumper/SM_VF8_FrontBumper_Luxury.uasset | K33: =IFERROR(VLOOKUP($A33,ITEM_MASTER!$A:$K,11,0),"?") | L33: =IFERROR(VLOOKUP($A33,ITEM_MASTER!$A:$N,12,0),"?") -> FALSE
A34: ccv_part_rb_0006 | B34: =MID(A34,FIND("_",A34) + 1,FIND(CHAR(160),SUBSTITUTE(A34,"_",CHAR(160),2)) - 1 - (FIND("_",A34))) -> part | C34: Rear Bumper | D34: car_vin_2 | E34: =IFERROR(VLOOKUP(A34,ITEM_MASTER!$A:$E,4,0),"?") -> Rear Bumper Luxury | F34: =IFERROR(VLOOKUP(A34,ITEM_MASTER!$A:$E,5,0),"?") -> Cản Sau Cao Cấp | G34: =IFERROR(VLOOKUP($A34,ITEM_MASTER!$A:$I,7,0),"?") -> Rare | H34: =IFERROR(VLOOKUP($A34,ITEM_MASTER!$A:$I,8,0),"?") -> unreleased | I34: =IFERROR(VLOOKUP($A34,ITEM_MASTER!$A:$I,9,0),"?") -> Post-Race Rewards | J34: =IFERROR(VLOOKUP($A34,ITEM_MASTER!$A:$J,10,0),"?") -> /Content/Vehicles/VF8/Mesh/RearBumper/SM_VF8_RearBumper_Luxury.uasset | K34: =IFERROR(VLOOKUP($A34,ITEM_MASTER!$A:$K,11,0),"?") | L34: =IFERROR(VLOOKUP($A34,ITEM_MASTER!$A:$N,12,0),"?") -> FALSE
A35: ccv_part_sp_0006 | B35: =MID(A35,FIND("_",A35) + 1,FIND(CHAR(160),SUBSTITUTE(A35,"_",CHAR(160),2)) - 1 - (FIND("_",A35))) -> part | C35: Spoiler | D35: car_vin_2 | E35: =IFERROR(VLOOKUP(A35,ITEM_MASTER!$A:$E,4,0),"?") -> Spoiler Luxury | F35: =IFERROR(VLOOKUP(A35,ITEM_MASTER!$A:$E,5,0),"?") -> Cánh Gió Cao Cấp | G35: =IFERROR(VLOOKUP($A35,ITEM_MASTER!$A:$I,7,0),"?") -> Rare | H35: =IFERROR(VLOOKUP($A35,ITEM_MASTER!$A:$I,8,0),"?") -> unreleased | I35: =IFERROR(VLOOKUP($A35,ITEM_MASTER!$A:$I,9,0),"?") -> Post-Race Rewards | J35: =IFERROR(VLOOKUP($A35,ITEM_MASTER!$A:$J,10,0),"?") -> /Content/Vehicles/VF8/Mesh/Spoiler/SM_VF8_Spoiler_Luxury.uasset | K35: =IFERROR(VLOOKUP($A35,ITEM_MASTER!$A:$K,11,0),"?") | L35: =IFERROR(VLOOKUP($A35,ITEM_MASTER!$A:$N,12,0),"?") -> FALSE
A36: ccv_part_ro_0006 | B36: =MID(A36,FIND("_",A36) + 1,FIND(CHAR(160),SUBSTITUTE(A36,"_",CHAR(160),2)) - 1 - (FIND("_",A36))) -> part | C36: Roof | D36: car_vin_2 | E36: =IFERROR(VLOOKUP(A36,ITEM_MASTER!$A:$E,4,0),"?") -> Roof Panel Luxury | F36: =IFERROR(VLOOKUP(A36,ITEM_MASTER!$A:$E,5,0),"?") -> Nóc Xe Cao Cấp | G36: =IFERROR(VLOOKUP($A36,ITEM_MASTER!$A:$I,7,0),"?") -> Rare | H36: =IFERROR(VLOOKUP($A36,ITEM_MASTER!$A:$I,8,0),"?") -> unreleased | I36: =IFERROR(VLOOKUP($A36,ITEM_MASTER!$A:$I,9,0),"?") -> Post-Race Rewards | J36: =IFERROR(VLOOKUP($A36,ITEM_MASTER!$A:$J,10,0),"?") -> /Content/Vehicles/VF8/Mesh/Roof/SM_VF8_Roof_Luxury.uasset | K36: =IFERROR(VLOOKUP($A36,ITEM_MASTER!$A:$K,11,0),"?") | L36: =IFERROR(VLOOKUP($A36,ITEM_MASTER!$A:$N,12,0),"?") -> FALSE
A37: ccv_part_wheel_0006 | B37: =MID(A37,FIND("_",A37) + 1,FIND(CHAR(160),SUBSTITUTE(A37,"_",CHAR(160),2)) - 1 - (FIND("_",A37))) -> part | C37: Wheel | D37: car_vin_2 | E37: =IFERROR(VLOOKUP(A37,ITEM_MASTER!$A:$E,4,0),"?") -> Wheel Luxury | F37: =IFERROR(VLOOKUP(A37,ITEM_MASTER!$A:$E,5,0),"?") -> Mâm Cao Cấp | G37: =IFERROR(VLOOKUP($A37,ITEM_MASTER!$A:$I,7,0),"?") -> Rare | H37: =IFERROR(VLOOKUP($A37,ITEM_MASTER!$A:$I,8,0),"?") -> unreleased | I37: =IFERROR(VLOOKUP($A37,ITEM_MASTER!$A:$I,9,0),"?") -> Post-Race Rewards | J37: =IFERROR(VLOOKUP($A37,ITEM_MASTER!$A:$J,10,0),"?") -> /Content/Vehicles/VF8/Mesh/Wheel/SM_VF8_Wheels_Luxury.uasset | K37: =IFERROR(VLOOKUP($A37,ITEM_MASTER!$A:$K,11,0),"?") | L37: =IFERROR(VLOOKUP($A37,ITEM_MASTER!$A:$N,12,0),"?") -> FALSE
A38: ccv_part_ss_0006 | B38: =MID(A38,FIND("_",A38) + 1,FIND(CHAR(160),SUBSTITUTE(A38,"_",CHAR(160),2)) - 1 - (FIND("_",A38))) -> part | C38: Side Skirt | D38: car_vin_2 | E38: =IFERROR(VLOOKUP(A38,ITEM_MASTER!$A:$E,4,0),"?") -> Side Skirt Luxury | F38: =IFERROR(VLOOKUP(A38,ITEM_MASTER!$A:$E,5,0),"?") -> Ốp Sườn Cao Cấp | G38: =IFERROR(VLOOKUP($A38,ITEM_MASTER!$A:$I,7,0),"?") -> Rare | H38: =IFERROR(VLOOKUP($A38,ITEM_MASTER!$A:$I,8,0),"?") -> unreleased | I38: =IFERROR(VLOOKUP($A38,ITEM_MASTER!$A:$I,9,0),"?") -> Post-Race Rewards | J38: =IFERROR(VLOOKUP($A38,ITEM_MASTER!$A:$J,10,0),"?") -> /Content/Vehicles/VF8/Mesh/SideSkirt/SM_VF8_SideBoard_Luxury.uasset | K38: =IFERROR(VLOOKUP($A38,ITEM_MASTER!$A:$K,11,0),"?") | L38: =IFERROR(VLOOKUP($A38,ITEM_MASTER!$A:$N,12,0),"?") -> FALSE
A39: ccv_part_fb_0007 | B39: =MID(A39,FIND("_",A39) + 1,FIND(CHAR(160),SUBSTITUTE(A39,"_",CHAR(160),2)) - 1 - (FIND("_",A39))) -> part | C39: Front Bumper | D39: car_mer_1 | E39: =IFERROR(VLOOKUP(A39,ITEM_MASTER!$A:$E,4,0),"?") -> Front Bumper Basic | F39: =IFERROR(VLOOKUP(A39,ITEM_MASTER!$A:$E,5,0),"?") -> Cản Trước Tiêu Chuẩn | G39: =IFERROR(VLOOKUP($A39,ITEM_MASTER!$A:$I,7,0),"?") -> Common | H39: =IFERROR(VLOOKUP($A39,ITEM_MASTER!$A:$I,8,0),"?") -> unreleased | I39: =IFERROR(VLOOKUP($A39,ITEM_MASTER!$A:$I,9,0),"?") -> Car Defaults | J39: =IFERROR(VLOOKUP($A39,ITEM_MASTER!$A:$J,10,0),"?") -> /Content/Vehicles/MercedesBenz_AMG_GT_R/Meshs/FrontBumper/SM_Mercedes_Benz_AMG_GT_FrontBumper.uasset | K39: =IFERROR(VLOOKUP($A39,ITEM_MASTER!$A:$K,11,0),"?") | L39: =IFERROR(VLOOKUP($A39,ITEM_MASTER!$A:$N,12,0),"?") -> FALSE
A40: ccv_part_rb_0007 | B40: =MID(A40,FIND("_",A40) + 1,FIND(CHAR(160),SUBSTITUTE(A40,"_",CHAR(160),2)) - 1 - (FIND("_",A40))) -> part | C40: Rear Bumper | D40: car_mer_1 | E40: =IFERROR(VLOOKUP(A40,ITEM_MASTER!$A:$E,4,0),"?") -> Rear Bumper Basic | F40: =IFERROR(VLOOKUP(A40,ITEM_MASTER!$A:$E,5,0),"?") -> Cản Sau Tiêu Chuẩn | G40: =IFERROR(VLOOKUP($A40,ITEM_MASTER!$A:$I,7,0),"?") -> Common | H40: =IFERROR(VLOOKUP($A40,ITEM_MASTER!$A:$I,8,0),"?") -> unreleased | I40: =IFERROR(VLOOKUP($A40,ITEM_MASTER!$A:$I,9,0),"?") -> Car Defaults | J40: =IFERROR(VLOOKUP($A40,ITEM_MASTER!$A:$J,10,0),"?") -> /Content/Vehicles/MercedesBenz_AMG_GT_R/Meshs/RearBumper/SM_Mercedes_Benz_AMG_GT_RearBumper.uasset | K40: =IFERROR(VLOOKUP($A40,ITEM_MASTER!$A:$K,11,0),"?") | L40: =IFERROR(VLOOKUP($A40,ITEM_MASTER!$A:$N,12,0),"?") -> FALSE
A41: ccv_part_sp_0007 | B41: =MID(A41,FIND("_",A41) + 1,FIND(CHAR(160),SUBSTITUTE(A41,"_",CHAR(160),2)) - 1 - (FIND("_",A41))) -> part | C41: Spoiler | D41: car_mer_1 | E41: =IFERROR(VLOOKUP(A41,ITEM_MASTER!$A:$E,4,0),"?") -> Spoiler Basic | F41: =IFERROR(VLOOKUP(A41,ITEM_MASTER!$A:$E,5,0),"?") -> Cánh Gió Tiêu Chuẩn | G41: =IFERROR(VLOOKUP($A41,ITEM_MASTER!$A:$I,7,0),"?") -> Common | H41: =IFERROR(VLOOKUP($A41,ITEM_MASTER!$A:$I,8,0),"?") -> unreleased | I41: =IFERROR(VLOOKUP($A41,ITEM_MASTER!$A:$I,9,0),"?") -> Car Defaults | J41: =IFERROR(VLOOKUP($A41,ITEM_MASTER!$A:$J,10,0),"?") -> /Content/Vehicles/MercedesBenz_AMG_GT_R/Meshs/Spoiler/SM_Mercedes_Benz_AMG_GT_Spoiler.uasset | K41: =IFERROR(VLOOKUP($A41,ITEM_MASTER!$A:$K,11,0),"?") | L41: =IFERROR(VLOOKUP($A41,ITEM_MASTER!$A:$N,12,0),"?") -> FALSE
A42: ccv_part_ro_0007 | B42: =MID(A42,FIND("_",A42) + 1,FIND(CHAR(160),SUBSTITUTE(A42,"_",CHAR(160),2)) - 1 - (FIND("_",A42))) -> part | C42: Roof | D42: car_mer_1 | E42: =IFERROR(VLOOKUP(A42,ITEM_MASTER!$A:$E,4,0),"?") -> Roof Panel Basic | F42: =IFERROR(VLOOKUP(A42,ITEM_MASTER!$A:$E,5,0),"?") -> Nóc Xe Tiêu Chuẩn | G42: =IFERROR(VLOOKUP($A42,ITEM_MASTER!$A:$I,7,0),"?") -> Common | H42: =IFERROR(VLOOKUP($A42,ITEM_MASTER!$A:$I,8,0),"?") -> unreleased | I42: =IFERROR(VLOOKUP($A42,ITEM_MASTER!$A:$I,9,0),"?") -> Car Defaults | J42: =IFERROR(VLOOKUP($A42,ITEM_MASTER!$A:$J,10,0),"?") -> /Content/Vehicles/MercedesBenz_AMG_GT_R/Meshs/Roof/SM_Mercedes_Benz_AMG_GT_Roof.uasset | K42: =IFERROR(VLOOKUP($A42,ITEM_MASTER!$A:$K,11,0),"?") | L42: =IFERROR(VLOOKUP($A42,ITEM_MASTER!$A:$N,12,0),"?") -> FALSE
A43: ccv_part_wheel_0007 | B43: =MID(A43,FIND("_",A43) + 1,FIND(CHAR(160),SUBSTITUTE(A43,"_",CHAR(160),2)) - 1 - (FIND("_",A43))) -> part | C43: Wheel | D43: car_mer_1 | E43: =IFERROR(VLOOKUP(A43,ITEM_MASTER!$A:$E,4,0),"?") -> Wheel Basic | F43: =IFERROR(VLOOKUP(A43,ITEM_MASTER!$A:$E,5,0),"?") -> Mâm Tiêu Chuẩn | G43: =IFERROR(VLOOKUP($A43,ITEM_MASTER!$A:$I,7,0),"?") -> Common | H43: =IFERROR(VLOOKUP($A43,ITEM_MASTER!$A:$I,8,0),"?") -> unreleased | I43: =IFERROR(VLOOKUP($A43,ITEM_MASTER!$A:$I,9,0),"?") -> Car Defaults | J43: =IFERROR(VLOOKUP($A43,ITEM_MASTER!$A:$J,10,0),"?") -> /Content/Vehicles/MercedesBenz_AMG_GT_R/Meshs/Wheel/SM_AMG_Wheels_Basic.uasset | K43: =IFERROR(VLOOKUP($A43,ITEM_MASTER!$A:$K,11,0),"?") | L43: =IFERROR(VLOOKUP($A43,ITEM_MASTER!$A:$N,12,0),"?") -> FALSE
... A140: ccv_dec_0012 | B140: =MID(A140,FIND("_",A140) + 1,FIND(CHAR(160),SUBSTITUTE(A140,"_",CHAR(160),2)) - 1 - (FIND("_",A140))) -> dec | C140: Decal | D140: car_mer_1 | E140: =IFERROR(VLOOKUP(A140,ITEM_MASTER!$A:$E,4,0),"?") -> Wraps | F140: =IFERROR(VLOOKUP(A140,ITEM_MASTER!$A:$E,5,0),"?") -> Decal Phủ | G140: =IFERROR(VLOOKUP($A140,ITEM_MASTER!$A:$I,7,0),"?") -> Common | H140: =IFERROR(VLOOKUP($A140,ITEM_MASTER!$A:$I,8,0),"?") -> unreleased | I140: =IFERROR(VLOOKUP($A140,ITEM_MASTER!$A:$I,9,0),"?") -> Post-Race Rewards | J140: =IFERROR(VLOOKUP($A140,ITEM_MASTER!$A:$J,10,0),"?") -> - | K140: =IFERROR(VLOOKUP($A140,ITEM_MASTER!$A:$K,11,0),"?") -> /Content/UI/Thumbnail_Folder/Customize_Skin/NoChange.uasset | L140: =IFERROR(VLOOKUP($A140,ITEM_MASTER!$A:$N,12,0),"?") -> FALSE
A141: ccv_dec_0013 | C141: Decal | E141: =IFERROR(VLOOKUP(A141,ITEM_MASTER!$A:$E,4,0),"?") -> Wraps | F141: =IFERROR(VLOOKUP(A141,ITEM_MASTER!$A:$E,5,0),"?") -> Decal Phủ 2 | G141: =IFERROR(VLOOKUP($A141,ITEM_MASTER!$A:$I,7,0),"?") -> Common | H141: =IFERROR(VLOOKUP($A141,ITEM_MASTER!$A:$I,8,0),"?") -> unreleased | I141: =IFERROR(VLOOKUP($A141,ITEM_MASTER!$A:$I,9,0),"?") -> Post-Race Rewards | J141: =IFERROR(VLOOKUP($A141,ITEM_MASTER!$A:$J,10,0),"?") -> - | K141: =IFERROR(VLOOKUP($A141,ITEM_MASTER!$A:$K,11,0),"?") -> /Content/UI/Thumbnail_Folder/Customize_Skin/NoChange.uasset | L141: =IFERROR(VLOOKUP($A141,ITEM_MASTER!$A:$N,12,0),"?") -> FALSE
A142: ccv_part_fb_0010 | C142: Front Bumper | D142: car_vin_1 | E142: =IFERROR(VLOOKUP(A142,ITEM_MASTER!$A:$E,4,0),"?") -> Front Bumper Signature | F142: =IFERROR(VLOOKUP(A142,ITEM_MASTER!$A:$E,5,0),"?") -> Cản Trước Đặc Trưng | G142: =IFERROR(VLOOKUP($A142,ITEM_MASTER!$A:$I,7,0),"?") -> Rare | H142: =IFERROR(VLOOKUP($A142,ITEM_MASTER!$A:$I,8,0),"?") -> unreleased | I142: =IFERROR(VLOOKUP($A142,ITEM_MASTER!$A:$I,9,0),"?") -> Shop Purchase | J142: =IFERROR(VLOOKUP($A142,ITEM_MASTER!$A:$J,10,0),"?") | K142: =IFERROR(VLOOKUP($A142,ITEM_MASTER!$A:$K,11,0),"?") | L142: =IFERROR(VLOOKUP($A142,ITEM_MASTER!$A:$N,12,0),"?") -> TRUE
A143: ccv_part_rb_0010 | C143: Rear Bumper | D143: car_vin_1 | E143: =IFERROR(VLOOKUP(A143,ITEM_MASTER!$A:$E,4,0),"?") -> Rear Bumper Signature | F143: =IFERROR(VLOOKUP(A143,ITEM_MASTER!$A:$E,5,0),"?") -> Cản Sau Đặc Trưng | G143: =IFERROR(VLOOKUP($A143,ITEM_MASTER!$A:$I,7,0),"?") -> Rare | H143: =IFERROR(VLOOKUP($A143,ITEM_MASTER!$A:$I,8,0),"?") -> unreleased | I143: =IFERROR(VLOOKUP($A143,ITEM_MASTER!$A:$I,9,0),"?") -> Shop Purchase | J143: =IFERROR(VLOOKUP($A143,ITEM_MASTER!$A:$J,10,0),"?") | K143: =IFERROR(VLOOKUP($A143,ITEM_MASTER!$A:$K,11,0),"?") | L143: =IFERROR(VLOOKUP($A143,ITEM_MASTER!$A:$N,12,0),"?") -> TRUE
A144: ccv_part_sp_0010 | C144: Spoiler | D144: car_vin_1 | E144: =IFERROR(VLOOKUP(A144,ITEM_MASTER!$A:$E,4,0),"?") -> Spoiler Signature | F144: =IFERROR(VLOOKUP(A144,ITEM_MASTER!$A:$E,5,0),"?") -> Cánh Gió Đặc Trưng | G144: =IFERROR(VLOOKUP($A144,ITEM_MASTER!$A:$I,7,0),"?") -> Rare | H144: =IFERROR(VLOOKUP($A144,ITEM_MASTER!$A:$I,8,0),"?") -> unreleased | I144: =IFERROR(VLOOKUP($A144,ITEM_MASTER!$A:$I,9,0),"?") -> Shop Purchase | J144: =IFERROR(VLOOKUP($A144,ITEM_MASTER!$A:$J,10,0),"?") | K144: =IFERROR(VLOOKUP($A144,ITEM_MASTER!$A:$K,11,0),"?") | L144: =IFERROR(VLOOKUP($A144,ITEM_MASTER!$A:$N,12,0),"?") -> TRUE
A145: ccv_part_ro_0010 | C145: Roof | D145: car_vin_1 | E145: =IFERROR(VLOOKUP(A145,ITEM_MASTER!$A:$E,4,0),"?") -> Roof Panel Signature | F145: =IFERROR(VLOOKUP(A145,ITEM_MASTER!$A:$E,5,0),"?") -> Nóc Xe Đặc Trưng | G145: =IFERROR(VLOOKUP($A145,ITEM_MASTER!$A:$I,7,0),"?") -> Rare | H145: =IFERROR(VLOOKUP($A145,ITEM_MASTER!$A:$I,8,0),"?") -> unreleased | I145: =IFERROR(VLOOKUP($A145,ITEM_MASTER!$A:$I,9,0),"?") -> Shop Purchase | J145: =IFERROR(VLOOKUP($A145,ITEM_MASTER!$A:$J,10,0),"?") | K145: =IFERROR(VLOOKUP($A145,ITEM_MASTER!$A:$K,11,0),"?") | L145: =IFERROR(VLOOKUP($A145,ITEM_MASTER!$A:$N,12,0),"?") -> TRUE
A146: ccv_part_wheel_0010 | C146: Wheel | D146: car_vin_1 | E146: =IFERROR(VLOOKUP(A146,ITEM_MASTER!$A:$E,4,0),"?") -> Wheel Signature | F146: =IFERROR(VLOOKUP(A146,ITEM_MASTER!$A:$E,5,0),"?") -> Mâm Đặc Trưng | G146: =IFERROR(VLOOKUP($A146,ITEM_MASTER!$A:$I,7,0),"?") -> Rare | H146: =IFERROR(VLOOKUP($A146,ITEM_MASTER!$A:$I,8,0),"?") -> unreleased | I146: =IFERROR(VLOOKUP($A146,ITEM_MASTER!$A:$I,9,0),"?") -> Shop Purchase | J146: =IFERROR(VLOOKUP($A146,ITEM_MASTER!$A:$J,10,0),"?") | K146: =IFERROR(VLOOKUP($A146,ITEM_MASTER!$A:$K,11,0),"?") | L146: =IFERROR(VLOOKUP($A146,ITEM_MASTER!$A:$N,12,0),"?") -> TRUE
A147: ccv_part_ss_0010 | C147: Side Skirt | D147: car_vin_1 | E147: =IFERROR(VLOOKUP(A147,ITEM_MASTER!$A:$E,4,0),"?") -> Side Skirt Signature | F147: =IFERROR(VLOOKUP(A147,ITEM_MASTER!$A:$E,5,0),"?") -> Ốp Sườn Đặc Trưng | G147: =IFERROR(VLOOKUP($A147,ITEM_MASTER!$A:$I,7,0),"?") -> Rare | H147: =IFERROR(VLOOKUP($A147,ITEM_MASTER!$A:$I,8,0),"?") -> unreleased | I147: =IFERROR(VLOOKUP($A147,ITEM_MASTER!$A:$I,9,0),"?") -> Shop Purchase | J147: =IFERROR(VLOOKUP($A147,ITEM_MASTER!$A:$J,10,0),"?") | K147: =IFERROR(VLOOKUP($A147,ITEM_MASTER!$A:$K,11,0),"?") | L147: =IFERROR(VLOOKUP($A147,ITEM_MASTER!$A:$N,12,0),"?") -> TRUE
A148: ccv_part_fb_0011 | C148: Front Bumper | D148: car_vin_2 | E148: =IFERROR(VLOOKUP(A148,ITEM_MASTER!$A:$E,4,0),"?") -> Front Bumper Signature | F148: =IFERROR(VLOOKUP(A148,ITEM_MASTER!$A:$E,5,0),"?") -> Cản Trước Đặc Trưng | G148: =IFERROR(VLOOKUP($A148,ITEM_MASTER!$A:$I,7,0),"?") -> Rare | H148: =IFERROR(VLOOKUP($A148,ITEM_MASTER!$A:$I,8,0),"?") -> unreleased | I148: =IFERROR(VLOOKUP($A148,ITEM_MASTER!$A:$I,9,0),"?") -> Shop Purchase | J148: =IFERROR(VLOOKUP($A148,ITEM_MASTER!$A:$J,10,0),"?") | K148: =IFERROR(VLOOKUP($A148,ITEM_MASTER!$A:$K,11,0),"?") | L148: =IFERROR(VLOOKUP($A148,ITEM_MASTER!$A:$N,12,0),"?") -> TRUE
A149: ccv_part_rb_0011 | C149: Rear Bumper | D149: car_vin_2 | E149: =IFERROR(VLOOKUP(A149,ITEM_MASTER!$A:$E,4,0),"?") -> Rear Bumper Signature | F149: =IFERROR(VLOOKUP(A149,ITEM_MASTER!$A:$E,5,0),"?") -> Cản Sau Đặc Trưng | G149: =IFERROR(VLOOKUP($A149,ITEM_MASTER!$A:$I,7,0),"?") -> Rare | H149: =IFERROR(VLOOKUP($A149,ITEM_MASTER!$A:$I,8,0),"?") -> unreleased | I149: =IFERROR(VLOOKUP($A149,ITEM_MASTER!$A:$I,9,0),"?") -> Shop Purchase | J149: =IFERROR(VLOOKUP($A149,ITEM_MASTER!$A:$J,10,0),"?") | K149: =IFERROR(VLOOKUP($A149,ITEM_MASTER!$A:$K,11,0),"?") | L149: =IFERROR(VLOOKUP($A149,ITEM_MASTER!$A:$N,12,0),"?") -> TRUE
A150: ccv_part_sp_0011 | C150: Spoiler | D150: car_vin_2 | E150: =IFERROR(VLOOKUP(A150,ITEM_MASTER!$A:$E,4,0),"?") -> Spoiler Signature | F150: =IFERROR(VLOOKUP(A150,ITEM_MASTER!$A:$E,5,0),"?") -> Cánh Gió Đặc Trưng | G150: =IFERROR(VLOOKUP($A150,ITEM_MASTER!$A:$I,7,0),"?") -> Rare | H150: =IFERROR(VLOOKUP($A150,ITEM_MASTER!$A:$I,8,0),"?") -> unreleased | I150: =IFERROR(VLOOKUP($A150,ITEM_MASTER!$A:$I,9,0),"?") -> Shop Purchase | J150: =IFERROR(VLOOKUP($A150,ITEM_MASTER!$A:$J,10,0),"?") | K150: =IFERROR(VLOOKUP($A150,ITEM_MASTER!$A:$K,11,0),"?") | L150: =IFERROR(VLOOKUP($A150,ITEM_MASTER!$A:$N,12,0),"?") -> TRUE
A151: ccv_part_ro_0011 | C151: Roof | D151: car_vin_2 | E151: =IFERROR(VLOOKUP(A151,ITEM_MASTER!$A:$E,4,0),"?") -> Roof Panel Signature | F151: =IFERROR(VLOOKUP(A151,ITEM_MASTER!$A:$E,5,0),"?") -> Nóc Xe Đặc Trưng | G151: =IFERROR(VLOOKUP($A151,ITEM_MASTER!$A:$I,7,0),"?") -> Rare | H151: =IFERROR(VLOOKUP($A151,ITEM_MASTER!$A:$I,8,0),"?") -> unreleased | I151: =IFERROR(VLOOKUP($A151,ITEM_MASTER!$A:$I,9,0),"?") -> Shop Purchase | J151: =IFERROR(VLOOKUP($A151,ITEM_MASTER!$A:$J,10,0),"?") | K151: =IFERROR(VLOOKUP($A151,ITEM_MASTER!$A:$K,11,0),"?") | L151: =IFERROR(VLOOKUP($A151,ITEM_MASTER!$A:$N,12,0),"?") -> TRUE
A152: ccv_part_wheel_0011 | C152: Wheel | D152: car_vin_2 | E152: =IFERROR(VLOOKUP(A152,ITEM_MASTER!$A:$E,4,0),"?") -> Wheel Signature | F152: =IFERROR(VLOOKUP(A152,ITEM_MASTER!$A:$E,5,0),"?") -> Mâm Đặc Trưng | G152: =IFERROR(VLOOKUP($A152,ITEM_MASTER!$A:$I,7,0),"?") -> Rare | H152: =IFERROR(VLOOKUP($A152,ITEM_MASTER!$A:$I,8,0),"?") -> unreleased | I152: =IFERROR(VLOOKUP($A152,ITEM_MASTER!$A:$I,9,0),"?") -> Shop Purchase | J152: =IFERROR(VLOOKUP($A152,ITEM_MASTER!$A:$J,10,0),"?") | K152: =IFERROR(VLOOKUP($A152,ITEM_MASTER!$A:$K,11,0),"?") | L152: =IFERROR(VLOOKUP($A152,ITEM_MASTER!$A:$N,12,0),"?") -> TRUE
...

Sheet CAR_REGISTRY
A1: car_id | B1: display_name_EN | C1: display_name_VN | D1: city_id | E1: city_name_VN | F1: archetype | G1: CR_base | H1: unlock_order | I1: notes | J1: file_path | K1: default_parts | L1: default_mat_body | M1: default_mat_wheel
A3: car_vin_1 | B3: Vin Fast LUX A 2.0 | C3: Vin Fast LUX A 2.0 | D3: DN | E3: Đà Nẵng | F3: Balance | G3: 1 | H3: 1 | I3: Starter car | J3: dẫn về body | K3: ccv_part_fb_01, ccv_part_rb_01, ccv_part_sp_01, ccv_part_ro_01, ccv_part_wheel_01, ccv_part_ss_01
A4: car_vin_2 | B4: Vin Fast VF8 | C4: Vin Fast VF8 | D4: DN | E4: Đà Nẵng | F4: Grip Focus | G4: 1 | H4: 2 | I4: Starter car | K4: ccv_part_fb_04, ccv_part_rb_04, ccv_part_sp_04, ccv_part_ro_04, ccv_part_wheel_04, ccv_part_ss_04
A5: car_mer_1 | B5: Mercedes-Benz AMG GT R | C5: Mercedes-Benz AMG GT R | D5: DN | E5: Đà Nẵng | F5: Speed Focus | G5: 1 | H5: 3 | I5: Starter car | K5: ccv_part_fb_07, ccv_part_rb_07, ccv_part_sp_07, ccv_part_ro_07, ccv_part_wheel_07, ccv_part_ss_07
A6: car_toy_1 | B6: Toyota GR86 | C6: Toyota GR86 | D6: HU | E6: Huế | F6: Balance | G6: 3 | H6: 4
A7: car_tes_1 | B7: Tesla Model S Plaid | C7: Tesla Model S Plaid | D7: HU | E7: Huế | F7: Grip Focus | G7: 3 | H7: 5
A8: car_por_1 | B8: Porsche 718 Cayman | C8: Porsche 718 Cayman | D8: HU | E8: Huế | F8: Speed Focus | G8: 3 | H8: 6
A9: car_toy_2 | B9: Lexus IS 500 Hybrid | C9: Lexus IS 500 Hybrid | D9: NT | E9: Nha Trang | F9: Balance | G9: 6 | H9: 7
A10: car_nis_1 | B10: Nissan GT-R | C10: Nissan GT-R | D10: NT | E10: Nha Trang | F10: Grip Focus | G10: 6 | H10: 8
A11: car_fer_1 | B11: Ferrari SF90 Stradale | C11: Ferrari SF90 Stradale | D11: NT | E11: Nha Trang | F11: Speed Focus | G11: 6 | H11: 9
A12: car_toy_3 | B12: Toyota lexus Electrified Sport | C12: Toyota lexus Electrified Sport | D12: HCM | E12: Hồ Chí Minh | F12: Balance | G12: 9 | H12: 10
A13: car_for_1 | B13: Ford Mustang GT500 | C13: Ford Mustang GT500 | D13: HCM | E13: Hồ Chí Minh | F13: Grip Focus | G13: 9 | H13: 11
A14: car_rim_1 | B14: Rimac Nevera | C14: Rimac Nevera | D14: HCM | E14: Hồ Chí Minh | F14: Speed Focus | G14: 9 | H14: 12
A15: car_bmw_1 | B15: BMW M3 GTR | C15: BMW M3 GTR | D15: PQ | E15: Phú Quốc | F15: Balance | G15: 12 | H15: 13
A16: car_lam_1 | B16: Lamborghini Huracán | C16: Lamborghini Huracán | D16: PQ | E16: Phú Quốc | F16: Grip Focus | G16: 12 | H16: 14
A17: car_bur_1 | B17: Bugatti Tourbillon | C17: Bugatti Tourbillon | D17: PQ | E17: Phú Quốc | F17: Speed Focus | G17: 12 | H17: 15
A18: car_mer_2 | B18: Mercedes Vision ATVR | C18: Mercedes Vision ATVR | G18: 2 | H18: - | I18: Shop Unlock
A19: car_dev_1 | B19: Devel Sixteen | C19: Devel Sixteen | G19: 5 | H19: - | I19: Shop Unlock
A20: car_spe_1 | B20: - | C20: - | G20: 11 | H20: - | I20: Shop Unlock

Sheet ITEM_PERF
A1: catalog_id | B1: subcategory | C1: upgrade_stage | D1: stat_primary | E1: stat_delta | F1: lv_required | G1: display_name_EN | H1: display_name_VN | I1: rarity | J1: status | K1: unlock_source | L1: file_path | N1: notes
G2: ← VLOOKUP → CATALOG_MASTER | H2: ← VLOOKUP → CATALOG_MASTER | I2: ← VLOOKUP → CATALOG_MASTER | J2: ← VLOOKUP → CATALOG_MASTER | K2: ← VLOOKUP → CATALOG_MASTER
A3: ccp_import_all_0001 | B3: import | C3: Stage 4 -6 | D3: All | E3: +1 | F3: 4 and Up | G3: =IFERROR(VLOOKUP(A3,ITEM_MASTER!$A:$E,4,0),"?") -> Upgrade Part | H3: =IFERROR(VLOOKUP(A3,ITEM_MASTER!$A:$E,5,0),"?") -> Gói nâng cấp xe | I3: =IFERROR(VLOOKUP($A3,ITEM_MASTER!$A:$I,7,0),"?") -> UnCommon | J3: =IFERROR(VLOOKUP($A3,ITEM_MASTER!$A:$I,8,0),"?") -> unreleased | K3: =IFERROR(VLOOKUP($A3,ITEM_MASTER!$A:$I,9,0),"?") -> Post-Race Rewards | L3: =IFERROR(VLOOKUP($A3,ITEM_MASTER!$A:$K,10,0),"?") -> path_f | M3: =IFERROR(VLOOKUP($A3,ITEM_MASTER!$A:$K,11,0),"?") -> path_i | N3: Cần để Upgrade xe từ lv 4-6
G4: =IFERROR(VLOOKUP(A4,ITEM_MASTER!$A:$E,4,0),"?") -> ? | H4: =IFERROR(VLOOKUP(A4,ITEM_MASTER!$A:$E,5,0),"?") -> ? | I4: =IFERROR(VLOOKUP($A4,ITEM_MASTER!$A:$H,7,0),"?") -> ? | L4: =IFERROR(VLOOKUP($A4,ITEM_MASTER!$A:$K,10,0),"?") -> ?
G5: =IFERROR(VLOOKUP(A5,ITEM_MASTER!$A:$E,4,0),"?") -> ? | H5: =IFERROR(VLOOKUP(A5,ITEM_MASTER!$A:$E,5,0),"?") -> ? | I5: =IFERROR(VLOOKUP($A5,ITEM_MASTER!$A:$H,7,0),"?") -> ? | L5: =IFERROR(VLOOKUP($A5,ITEM_MASTER!$A:$K,10,0),"?") -> ?
G6: =IFERROR(VLOOKUP(A6,ITEM_MASTER!$A:$E,4,0),"?") -> ? | H6: =IFERROR(VLOOKUP(A6,ITEM_MASTER!$A:$E,5,0),"?") -> ? | I6: =IFERROR(VLOOKUP($A6,ITEM_MASTER!$A:$H,7,0),"?") -> ? | L6: =IFERROR(VLOOKUP($A6,ITEM_MASTER!$A:$K,10,0),"?") -> ?
G7: =IFERROR(VLOOKUP(A7,ITEM_MASTER!$A:$E,4,0),"?") -> ? | H7: =IFERROR(VLOOKUP(A7,ITEM_MASTER!$A:$E,5,0),"?") -> ? | I7: =IFERROR(VLOOKUP($A7,ITEM_MASTER!$A:$H,7,0),"?") -> ? | L7: =IFERROR(VLOOKUP($A7,ITEM_MASTER!$A:$K,10,0),"?") -> ?
G8: =IFERROR(VLOOKUP(A8,ITEM_MASTER!$A:$E,4,0),"?") -> ? | H8: =IFERROR(VLOOKUP(A8,ITEM_MASTER!$A:$E,5,0),"?") -> ? | I8: =IFERROR(VLOOKUP($A8,ITEM_MASTER!$A:$H,7,0),"?") -> ? | L8: =IFERROR(VLOOKUP($A8,ITEM_MASTER!$A:$K,10,0),"?") -> ?
G9: =IFERROR(VLOOKUP(A9,ITEM_MASTER!$A:$E,4,0),"?") -> ? | H9: =IFERROR(VLOOKUP(A9,ITEM_MASTER!$A:$E,5,0),"?") -> ? | I9: =IFERROR(VLOOKUP($A9,ITEM_MASTER!$A:$H,7,0),"?") -> ? | L9: =IFERROR(VLOOKUP($A9,ITEM_MASTER!$A:$K,10,0),"?") -> ?
G10: =IFERROR(VLOOKUP(A10,ITEM_MASTER!$A:$E,4,0),"?") -> ? | H10: =IFERROR(VLOOKUP(A10,ITEM_MASTER!$A:$E,5,0),"?") -> ? | I10: =IFERROR(VLOOKUP($A10,ITEM_MASTER!$A:$H,7,0),"?") -> ? | L10: =IFERROR(VLOOKUP($A10,ITEM_MASTER!$A:$K,10,0),"?") -> ?
G11: =IFERROR(VLOOKUP(A11,ITEM_MASTER!$A:$E,4,0),"?") -> ? | H11: =IFERROR(VLOOKUP(A11,ITEM_MASTER!$A:$E,5,0),"?") -> ? | I11: =IFERROR(VLOOKUP($A11,ITEM_MASTER!$A:$H,7,0),"?") -> ? | L11: =IFERROR(VLOOKUP($A11,ITEM_MASTER!$A:$K,10,0),"?") -> ?
G12: =IFERROR(VLOOKUP(A12,ITEM_MASTER!$A:$E,4,0),"?") -> ? | H12: =IFERROR(VLOOKUP(A12,ITEM_MASTER!$A:$E,5,0),"?") -> ? | I12: =IFERROR(VLOOKUP($A12,ITEM_MASTER!$A:$H,7,0),"?") -> ? | L12: =IFERROR(VLOOKUP($A12,ITEM_MASTER!$A:$K,10,0),"?") -> ?
G13: =IFERROR(VLOOKUP(A13,ITEM_MASTER!$A:$E,4,0),"?") -> ? | H13: =IFERROR(VLOOKUP(A13,ITEM_MASTER!$A:$E,5,0),"?") -> ? | I13: =IFERROR(VLOOKUP($A13,ITEM_MASTER!$A:$H,7,0),"?") -> ? | L13: =IFERROR(VLOOKUP($A13,ITEM_MASTER!$A:$K,10,0),"?") -> ?
G14: =IFERROR(VLOOKUP(A14,ITEM_MASTER!$A:$E,4,0),"?") -> ? | H14: =IFERROR(VLOOKUP(A14,ITEM_MASTER!$A:$E,5,0),"?") -> ? | I14: =IFERROR(VLOOKUP($A14,ITEM_MASTER!$A:$H,7,0),"?") -> ? | L14: =IFERROR(VLOOKUP($A14,ITEM_MASTER!$A:$K,10,0),"?") -> ?
G15: =IFERROR(VLOOKUP(A15,ITEM_MASTER!$A:$E,4,0),"?") -> ? | H15: =IFERROR(VLOOKUP(A15,ITEM_MASTER!$A:$E,5,0),"?") -> ? | I15: =IFERROR(VLOOKUP($A15,ITEM_MASTER!$A:$H,7,0),"?") -> ? | L15: =IFERROR(VLOOKUP($A15,ITEM_MASTER!$A:$K,10,0),"?") -> ?
... G24: =IFERROR(VLOOKUP(A24,ITEM_MASTER!$A:$E,4,0),"?") -> ? | H24: =IFERROR(VLOOKUP(A24,ITEM_MASTER!$A:$E,5,0),"?") -> ? | I24: =IFERROR(VLOOKUP($A24,ITEM_MASTER!$A:$H,7,0),"?") -> ? | L24: =IFERROR(VLOOKUP($A24,ITEM_MASTER!$A:$K,10,0),"?") -> ?

Sheet CITY_LOOT_POOL
A1: City Loot Pool — filter city_id để xem theo thành phố · item_category/subcategory/display_name tự động VLOOKUP từ CATALOG_MASTER
A2: city_id | B2: city_name_VN | C2: item_master_id | D2: item_category | E2: item_subcategory | F2: display_name_EN | G2: display_name_VN | H2: base_weights | I2: rarity_tier | J2: status | K2: unlock_source | L2: notes
A3: ── DN Đà Nẵng ──────────────────
A4: DN | B4: Đà Nẵng | C4: ccv_part_fb_0001 | D4: =IFERROR(VLOOKUP(C4,ITEM_MASTER!$A:$C,2,0),"?") -> ccv | E4: =IFERROR(VLOOKUP(C4,ITEM_MASTER!$A:$C,3,0),"?") -> part | F4: =IFERROR(VLOOKUP($C4,ITEM_MASTER!$A:$D,4,0),"?") -> Front Bumper Basic | G4: =IFERROR(VLOOKUP($C4,ITEM_MASTER!$A:$I,5,0),"?") -> Cản Trước Tiêu Chuẩn | H4: 0.5 | I4: =IFERROR(VLOOKUP($C4,ITEM_MASTER!$A:$N,7,0),"?") -> Common | J4: =IFERROR(VLOOKUP($C4,ITEM_MASTER!$A:$N,8,0),"?") -> unreleased | K4: =IFERROR(VLOOKUP($C4,ITEM_MASTER!$A:$N,9,0),"?") -> Car Defaults
A5: DN | B5: Đà Nẵng | C5: ccv_part_rb_0001 | D5: =IFERROR(VLOOKUP(C5,ITEM_MASTER!$A:$C,2,0),"?") -> ccv | E5: =IFERROR(VLOOKUP(C5,ITEM_MASTER!$A:$C,3,0),"?") -> part | F5: =IFERROR(VLOOKUP(C5,ITEM_MASTER!$A:$D,4,0),"?") -> Rear Bumper Basic | G5: =IFERROR(VLOOKUP($C5,ITEM_MASTER!$A:$I,5,0),"?") -> Cản Sau Tiêu Chuẩn | H5: 0.5 | I5: =IFERROR(VLOOKUP($C5,ITEM_MASTER!$A:$N,7,0),"?") -> Common | J5: =IFERROR(VLOOKUP($C5,ITEM_MASTER!$A:$N,8,0),"?") -> unreleased | K5: =IFERROR(VLOOKUP($C5,ITEM_MASTER!$A:$N,9,0),"?") -> Car Defaults
A6: DN | B6: Đà Nẵng | C6: ccv_part_sp_0001 | D6: =IFERROR(VLOOKUP(C6,ITEM_MASTER!$A:$C,2,0),"?") -> ccv | E6: =IFERROR(VLOOKUP(C6,ITEM_MASTER!$A:$C,3,0),"?") -> part | F6: =IFERROR(VLOOKUP(C6,ITEM_MASTER!$A:$D,4,0),"?") -> Spoiler Basic | G6: =IFERROR(VLOOKUP($C6,ITEM_MASTER!$A:$I,5,0),"?") -> Cánh Gió Tiêu Chuẩn | H6: 0.5 | I6: =IFERROR(VLOOKUP($C6,ITEM_MASTER!$A:$N,7,0),"?") -> Common | J6: =IFERROR(VLOOKUP($C6,ITEM_MASTER!$A:$N,8,0),"?") -> unreleased | K6: =IFERROR(VLOOKUP($C6,ITEM_MASTER!$A:$N,9,0),"?") -> Car Defaults
